Workbook

Sheet Valuation>
A1: #

Sheet DE 40 Valuation
A1: #
H2: 20 Years | I2: 10 Years | J2: 20 years | K2: 20 years
B3: Valuation of DE 40 Price Kursindex | E3: =IF(OR(C6="",C7="",C8="",C9="",C10=""),"Provide Correct Inputs",SUM(E13:E23)) -> 13960.104 | H3: 15 Years | I3: 7 Years | J3: 15 years | K3: 15 years
B4: Key Inputs | D4: Assumptions | E4: =IF(OR(C6="",C7="",C8="",C9="",C10=""),"Provide Correct Inputs",IF(E3>1.05*(C6),"Undervalued",IF(E3<0.95*C6,"Overvalued","Fairly Valued"))) -> Undervalued | H4: 10 Years | I4: 5 Years | J4: 10 years | K4: 10 years
B5: Data | C5: =TODAY() -> 46270 | D5: 46207 | H5: 7 Years | I5: 3 Years | J5: 7 years | K5: 7 years
B6: Current DE40 Level | C6: 9175 | D6: =C6 -> 9175 | E6: =IF(OR(C6="",C7="",C8="",C9="",C10=""),"Provide Correct Inputs","The Market implied fair value of DE40 is : "&ROUNDUP(E3,0)&". The DE40 is currently trading at: "&ROUNDUP(C6,0)&". A "&TEXT(ABS((D6-E3)/D6),"0.00%")&" "&IF(E4="Undervalued","appreciation",IF(E4="Overvalued","correction","adjustment"))&" expected from this level") -> The Market implied fair value of DE40 is : 13961. The DE40 is currently trading at: 9175. A 52.15% appreciation expected from this level | H6: 5 Years | J6: 5 years | K6: 5 years
B7: Total Yield | C7: 3 Years | D7: =VLOOKUP(C7,'Expected Dividend & BuyBack'!K3:L13,2,FALSE) -> 0.044783829 | H7: 3 Years | J7: Latest | K7: Latest
B8: Expected Growth | C8: 3 Years | D8: =VLOOKUP(C8,'DE 40 EPSGrowth'!L3:M9,2,FALSE) -> 0.098959983 | J8: Risk free rate using CDS Approach
B9: Risk Free Rate | C9: Risk free rate using CDS Approach | D9: =VLOOKUP(C9,'Risk Free Rate Calculation'!M3:N15,2,FALSE) -> 0.028276
B10: Equity Risk Premium | C10: Latest | D10: =VLOOKUP(C10,'ERP Historical Data'!F10:G20,2,FALSE) -> 0.05415361
B11: Cost of Equity | D11: =SUM(D9:D10) -> 0.08242961
B12: Year | C12: Expected Dividends and BuyBacks | D12: Cummulative PV Factor ( Risk Free Rate +Equity Risk Premium) | E12: Present Value of Expected Dividends and Buybacks
B13: 2026 | C13: =$D$6*$D$7*((1+$D$8)^(B13-YEAR($D$5))) -> 410.89163 | D13: =1/((1+$D$11)^(B13-YEAR($D$5))) -> 1 | E13: =C13*D13 -> 410.89163
B14: =B13+1 -> 2027 | C14: =$D$6*$D$7*((1+$D$8)^(B14-YEAR($D$5))) -> 451.55346 | D14: =1/((1+$D$11)^(B14-YEAR($D$5))) -> 0.9238476 | E14: =C14*D14 -> 417.16658
B15: =B14+1 -> 2028 | C15: =$D$6*$D$7*((1+$D$8)^(B15-YEAR($D$5))) -> 496.23918 | D15: =1/((1+$D$11)^(B15-YEAR($D$5))) -> 0.85349439 | E15: =C15*D15 -> 423.53736
B16: =B15+1 -> 2029 | C16: =$D$6*$D$7*((1+$D$8)^(B16-YEAR($D$5))) -> 545.347 | D16: =1/((1+$D$11)^(B16-YEAR($D$5))) -> 0.78849875 | E16: =C16*D16 -> 430.00543
B17: =B16+1 -> 2030 | C17: =$D$6*$D$7*((1+$D$8)^(B17-YEAR($D$5))) -> 599.31453 | D17: =1/((1+$D$11)^(B17-YEAR($D$5))) -> 0.72845268 | E17: =C17*D17 -> 436.57227
B18: =B17+1 -> 2031 | C18: =$D$6*$D$7*((1+$D$8)^(B18-YEAR($D$5))) -> 658.62268 | D18: =1/((1+$D$11)^(B18-YEAR($D$5))) -> 0.67297926 | E18: =C18*D18 -> 443.23941
B19: =B18+1 -> 2032 | C19: =$D$6*$D$7*((1+$D$8)^(B19-YEAR($D$5))) -> 723.79997 | D19: =1/((1+$D$11)^(B19-YEAR($D$5))) -> 0.62173027 | E19: =C19*D19 -> 450.00836
B20: =B19+1 -> 2033 | C20: =$D$6*$D$7*((1+$D$8)^(B20-YEAR($D$5))) -> 795.42721 | D20: =1/((1+$D$11)^(B20-YEAR($D$5))) -> 0.57438402 | E20: =C20*D20 -> 456.88068
B21: =B20+1 -> 2034 | C21: =$D$6*$D$7*((1+$D$8)^(B21-YEAR($D$5))) -> 874.14267 | D21: =1/((1+$D$11)^(B21-YEAR($D$5))) -> 0.5306433 | E21: =C21*D21 -> 463.85795
B22: =B21+1 -> 2035 | C22: =$D$6*$D$7*((1+$D$8)^(B22-YEAR($D$5))) -> 960.64781 | D22: =1/((1+$D$11)^(B22-YEAR($D$5))) -> 0.49023354 | E22: =C22*D22 -> 470.94178
B23: =B22&"- ∞" -> 2035- ∞ | C23: =C22*(1+D8)/D10 -> 19494.794 | D23: =1/((1+$D$11)^(B22-YEAR($D$5))) -> 0.49023354 | E23: =C23*D23 -> 9557.0021

Sheet Data>
A1: #

Sheet Expected Dividend & BuyBack
A1: # | D1: Need to update from this column
B2: Year | C2: DE40 Average Range | D2: Dividend Yield | E2: Dividend Amount | F2: BuyBack Amount | G2: Total Earnings | H2: Total Earning Yield
B3: ='DE 40 Historical Data'!B5 -> 2002 | C3: ='DE 40 Historical Data'!C5 -> 2141.78 | D3: =((1+'DE 40 Perf Historical Data'!I4)/(1+'DE 40 Historical Data'!D5))-1 -> 0.017485144 | E3: =C3*D3 -> 37.449331 | F3: =E3*'Dividend Payout Ratio 2025 - 26'!$O$16 -> 27.314104 | G3: =SUM(E3:F3) -> 64.763436 | H3: =G3/C3 -> 0.030238136 | J3: Average DE 40 Earning Yield | K3: 20 Years | L3: =AVERAGE(H7:H26) -> 0.052576297
B4: ='DE 40 Historical Data'!B6 -> 2003 | C4: ='DE 40 Historical Data'!C6 -> 2857.84 | D4: =((1+'DE 40 Perf Historical Data'!I5)/(1+'DE 40 Historical Data'!D6))-1 -> 0.027317719 | E4: =C4*D4 -> 78.069669 | F4: =E4*'Dividend Payout Ratio 2025 - 26'!$O$16 -> 56.941019 | G4: =SUM(E4:F4) -> 135.01069 | H4: =G4/C4 -> 0.047242213
B5: ='DE 40 Historical Data'!B7 -> 2004 | C5: ='DE 40 Historical Data'!C7 -> 3004.65 | D5: =((1+'DE 40 Perf Historical Data'!I6)/(1+'DE 40 Historical Data'!D7))-1 -> 0.022292913 | E5: =C5*D5 -> 66.982402 | F5: =E5*'Dividend Payout Ratio 2025 - 26'!$O$16 -> 48.854392 | G5: =SUM(E5:F5) -> 115.83679 | H5: =G5/C5 -> 0.038552508 | J5: =J3 -> Average DE 40 Earning Yield | K5: 15 Years | L5: =AVERAGE(H12:H26) -> 0.05106116
B6: ='DE 40 Historical Data'!B8 -> 2005 | C6: ='DE 40 Historical Data'!C8 -> 3719.79 | D6: =((1+'DE 40 Perf Historical Data'!I7)/(1+'DE 40 Historical Data'!D8))-1 -> 0.034577671 | E6: =C6*D6 -> 128.62168 | F6: =E6*'Dividend Payout Ratio 2025 - 26'!$O$16 -> 93.811712 | G6: =SUM(E6:F6) -> 222.43339 | H6: =G6/C6 -> 0.059797297
B7: ='DE 40 Historical Data'!B9 -> 2006 | C7: ='DE 40 Historical Data'!C9 -> 4429.01 | D7: =((1+'DE 40 Perf Historical Data'!I8)/(1+'DE 40 Historical Data'!D9))-1 -> 0.01730797 | E7: =C7*D7 -> 76.657173 | F7: =E7*'Dividend Payout Ratio 2025 - 26'!$O$16 -> 55.910799 | G7: =SUM(E7:F7) -> 132.56797 | H7: =G7/C7 -> 0.029931739 | J7: =J5 -> Average DE 40 Earning Yield | K7: 10 Years | L7: =AVERAGE(H15:H26) -> 0.050445533
B8: ='DE 40 Historical Data'!B10 -> 2007 | C8: ='DE 40 Historical Data'!C10 -> 5277.23 | D8: =((1+'DE 40 Perf Historical Data'!I9)/(1+'DE 40 Historical Data'!D10))-1 -> 0.024022637 | E8: =C8*D8 -> 126.77298 | F8: =E8*'Dividend Payout Ratio 2025 - 26'!$O$16 -> 92.463345 | G8: =SUM(E8:F8) -> 219.23633 | H8: =G8/C8 -> 0.041543826
B9: ='DE 40 Historical Data'!B11 -> 2008 | C9: ='DE 40 Historical Data'!C11 -> 3041.6 | D9: =((1+'DE 40 Perf Historical Data'!I10)/(1+'DE 40 Historical Data'!D11))-1 -> 0.034517337 | E9: =C9*D9 -> 104.98793 | F9: =E9*'Dividend Payout Ratio 2025 - 26'!$O$16 -> 76.574165 | G9: =SUM(E9:F9) -> 181.5621 | H9: =G9/C9 -> 0.059692956 | J9: =J7 -> Average DE 40 Earning Yield | K9: 7 Years | L9: =AVERAGE(H18:H26) -> 0.051061642
B10: ='DE 40 Historical Data'!B12 -> 2009 | C10: ='DE 40 Historical Data'!C12 -> 3604.02 | D10: =((1+'DE 40 Perf Historical Data'!I11)/(1+'DE 40 Historical Data'!D12))-1 -> 0.054722563 | E10: =C10*D10 -> 197.22121 | F10: =E10*'Dividend Payout Ratio 2025 - 26'!$O$16 -> 143.84558 | G10: =SUM(E10:F10) -> 341.06679 | H10: =G10/C10 -> 0.0946351
B11: ='DE 40 Historical Data'!B13 -> 2010 | C11: ='DE 40 Historical Data'!C13 -> 4053.71 | D11: =((1+'DE 40 Perf Historical Data'!I12)/(1+'DE 40 Historical Data'!D13))-1 -> 0.034582078 | E11: =C11*D11 -> 140.18572 | F11: =E11*'Dividend Payout Ratio 2025 - 26'!$O$16 -> 102.24608 | G11: =SUM(E11:F11) -> 242.43179 | H11: =G11/C11 -> 0.059804918 | J11: =J9 -> Average DE 40 Earning Yield | K11: 5 Years | L11: =AVERAGE(H22:H26) -> 0.048683401
B12: ='DE 40 Historical Data'!B14 -> 2011 | C12: ='DE 40 Historical Data'!C14 -> 3346.06 | D12: =((1+'DE 40 Perf Historical Data'!I13)/(1+'DE 40 Historical Data'!D14))-1 -> 0.02148641 | E12: =C12*D12 -> 71.894816 | F12: =E12*'Dividend Payout Ratio 2025 - 26'!$O$16 -> 52.437318 | G12: =SUM(E12:F12) -> 124.33213 | H12: =G12/C12 -> 0.037157772
B13: ='DE 40 Historical Data'!B15 -> 2012 | C13: ='DE 40 Historical Data'!C15 -> 4161.3 | D13: =((1+'DE 40 Perf Historical Data'!I14)/(1+'DE 40 Historical Data'!D15))-1 -> 0.037755846 | E13: =C13*D13 -> 157.1134 | F13: =E13*'Dividend Payout Ratio 2025 - 26'!$O$16 -> 114.59248 | G13: =SUM(E13:F13) -> 271.70588 | H13: =G13/C13 -> 0.06529351 | J13: =J11 -> Average DE 40 Earning Yield | K13: 3 Years | L13: =AVERAGE(H24:H26) -> 0.044783829
B14: ='DE 40 Historical Data'!B16 -> 2013 | C14: ='DE 40 Historical Data'!C16 -> 5051.89 | D14: =((1+'DE 40 Perf Historical Data'!I15)/(1+'DE 40 Historical Data'!D16))-1 -> 0.033607612 | E14: =C14*D14 -> 169.78196 | F14: =E14*'Dividend Payout Ratio 2025 - 26'!$O$16 -> 123.83244 | G14: =SUM(E14:F14) -> 293.6144 | H14: =G14/C14 -> 0.058119714
B15: ='DE 40 Historical Data'!B17 -> 2014 | C15: ='DE 40 Historical Data'!C17 -> 5044.71 | D15: =((1+'DE 40 Perf Historical Data'!I16)/(1+'DE 40 Historical Data'!D17))-1 -> 0.040734139 | E15: =C15*D15 -> 205.49192 | F15: =E15*'Dividend Payout Ratio 2025 - 26'!$O$16 -> 149.87792 | G15: =SUM(E15:F15) -> 355.36984 | H15: =G15/C15 -> 0.070444057
B16: ='DE 40 Historical Data'!B18 -> 2015 | C16: ='DE 40 Historical Data'!C18 -> 5390.31 | D16: =((1+'DE 40 Perf Historical Data'!I17)/(1+'DE 40 Historical Data'!D18))-1 -> 0.023844915 | E16: =C16*D16 -> 128.53148 | F16: =E16*'Dividend Payout Ratio 2025 - 26'!$O$16 -> 93.745929 | G16: =SUM(E16:F16) -> 222.27741 | H16: =G16/C16 -> 0.04123648
B17: ='DE 40 Historical Data'!B19 -> 2016 | C17: ='DE 40 Historical Data'!C19 -> 5588.27 | D17: =((1+'DE 40 Perf Historical Data'!I18)/(1+'DE 40 Historical Data'!D19))-1 -> 0.019724665 | E17: =C17*D17 -> 110.22675 | F17: =E17*'Dividend Payout Ratio 2025 - 26'!$O$16 -> 80.395161 | G17: =SUM(E17:F17) -> 190.62191 | H17: =G17/C17 -> 0.034111078
B18: ='DE 40 Historical Data'!B20 -> 2017 | C18: ='DE 40 Historical Data'!C20 -> 6122.26 | D18: =((1+'DE 40 Perf Historical Data'!I19)/(1+'DE 40 Historical Data'!D20))-1 -> 0.031944428 | E18: =C18*D18 -> 195.57209 | F18: =E18*'Dividend Payout Ratio 2025 - 26'!$O$16 -> 142.64277 | G18: =SUM(E18:F18) -> 338.21486 | H18: =G18/C18 -> 0.055243466
B19: ='DE 40 Historical Data'!B21 -> 2018 | C19: ='DE 40 Historical Data'!C21 -> 4862.74 | D19: =((1+'DE 40 Perf Historical Data'!I20)/(1+'DE 40 Historical Data'!D21))-1 -> 0.024186813 | E19: =C19*D19 -> 117.61418 | F19: =E19*'Dividend Payout Ratio 2025 - 26'!$O$16 -> 85.783268 | G19: =SUM(E19:F19) -> 203.39745 | H19: =G19/C19 -> 0.041827745
B20: ='DE 40 Historical Data'!B22 -> 2019 | C20: ='DE 40 Historical Data'!C22 -> 5909.66 | D20: =((1+'DE 40 Perf Historical Data'!I21)/(1+'DE 40 Historical Data'!D22))-1 -> 0.032478073 | E20: =C20*D20 -> 191.93437 | F20: =E20*'Dividend Payout Ratio 2025 - 26'!$O$16 -> 139.98956 | G20: =SUM(E20:F20) -> 331.92393 | H20: =G20/C20 -> 0.056166333
B21: ='DE 40 Historical Data'!B23 -> 2020 | C21: ='DE 40 Historical Data'!C23 -> 5935.22 | D21: =((1+'DE 40 Perf Historical Data'!I22)/(1+'DE 40 Historical Data'!D23))-1 -> 0.036371938 | E21: =C21*D21 -> 215.87546 | F21: =E21*'Dividend Payout Ratio 2025 - 26'!$O$16 -> 157.45127 | G21: =SUM(E21:F21) -> 373.32672 | H21: =G21/C21 -> 0.062900233
B22: ='DE 40 Historical Data'!B24 -> 2021 | C22: ='DE 40 Historical Data'!C24 -> 6709.66 | D22: =((1+'DE 40 Perf Historical Data'!I23)/(1+'DE 40 Historical Data'!D24))-1 -> 0.023991771 | E22: =C22*D22 -> 160.97662 | F22: =E22*'Dividend Payout Ratio 2025 - 26'!$O$16 -> 117.41017 | G22: =SUM(E22:F22) -> 278.38679 | H22: =G22/C22 -> 0.041490447
B23: ='DE 40 Historical Data'!B25 -> 2022 | C23: ='DE 40 Historical Data'!C25 -> 5692.03 | D23: =((1+'DE 40 Perf Historical Data'!I24)/(1+'DE 40 Historical Data'!D25))-1 -> 0.039075155 | E23: =C23*D23 -> 222.41695 | F23: =E23*'Dividend Payout Ratio 2025 - 26'!$O$16 -> 162.22238 | G23: =SUM(E23:F23) -> 384.63934 | H23: =G23/C23 -> 0.067575072
B24: ='DE 40 Historical Data'!B26 -> 2023 | C24: ='DE 40 Historical Data'!C26 -> 6628.85 | D24: =((1+'DE 40 Perf Historical Data'!I25)/(1+'DE 40 Historical Data'!D26))-1 -> 0.022207669 | E24: =C24*D24 -> 147.21131 | F24: =E24*'Dividend Payout Ratio 2025 - 26'!$O$16 -> 107.37028 | G24: =SUM(E24:F24) -> 254.58158 | H24: =G24/C24 -> 0.03840509
B25: 2024 | C25: ='DE 40 Historical Data'!C27 -> 7648.55 | D25: =((1+'DE 40 Perf Historical Data'!I26)/(1+'DE 40 Historical Data'!D27))-1 -> 0.030040381 | E25: =C25*D25 -> 229.76536 | F25: =E25*'Dividend Payout Ratio 2025 - 26'!$O$16 -> 167.58203 | G25: =SUM(E25:F25) -> 397.34739 | H25: =G25/C25 -> 0.051950682
B26: 2025 | C26: ='DE 40 Historical Data'!C28 -> 9175.13 | D26: =((1+'DE 40 Perf Historical Data'!I27)/(1+'DE 40 Historical Data'!D28))-1 -> 0.025440436 | E26: =C26*D26 -> 233.41931 | F26: =E26*'Dividend Payout Ratio 2025 - 26'!$O$16 -> 170.24708 | G26: =SUM(E26:F26) -> 403.66639 | H26: =G26/C26 -> 0.043995714

Sheet DE 40 EPSGrowth
A1: #
A3: # | B3: Year | C3: DE 40 Average Range | D3: PE Ratios | E3: EPS | F3: EPS CAGR 3 Yr | G3: EPS CAGR 5 Yr | H3: EPS CAGR 7 Yr | I3: EPS CAGR 10 Yr | K3: Average EPS CAGR | L3: 10 Years | M3: =AVERAGE(I14:I30) -> 0.053306061 | S3: Year Wise Average P/E
B4: ='DE 40 Historical Data'!B3 -> 2000 | C4: ='DE 40 Historical Data'!C3 -> 4934.85 | D4: =T5 -> 17.9669 | E4: =C4/D4 -> 274.66341 | F4: - | G4: - | H4: - | I4: - | P4: Date | Q4: DE 40 P/E | S4: Year | T4: P/E
B5: ='DE 40 Historical Data'!B4 -> 2001 | C5: ='DE 40 Historical Data'!C4 -> 3887.48 | D5: =T6 -> 45.08235 | E5: =C5/D5 -> 86.230642 | F5: - | G5: - | H5: - | I5: - | K5: Average EPS CAGR | L5: 7 Years | M5: =AVERAGE(H11:H30) -> 0.059459099 | P5: 34700 | Q5: 25.4169 | S5: 2001 | T5: =AVERAGEIFS($Q$5:$Q$382,$P$5:$P$382,">="&DATE(S5,1,1),$P$5:$P$382,"<="&DATE(S5,12,31)) -> 17.9669
B6: ='DE 40 Historical Data'!B5 -> 2002 | C6: ='DE 40 Historical Data'!C5 -> 2141.78 | D6: =T7 -> 58.0532 | E6: =C6/D6 -> 36.893401 | G6: - | H6: - | I6: - | P6: 34881 | Q6: 28.0013 | S6: =S5+1 -> 2002 | T6: =AVERAGEIFS($Q$5:$Q$382,$P$5:$P$382,">="&DATE(S6,1,1),$P$5:$P$382,"<="&DATE(S6,12,31)) -> 45.08235
B7: ='DE 40 Historical Data'!B6 -> 2003 | C7: ='DE 40 Historical Data'!C6 -> 2857.84 | D7: =T8 -> 22.7272 | E7: =C7/D7 -> 125.74536 | F7: =_xlfn.RRI(3,E4,E7) -> -0.22927924 | G7: - | H7: - | I7: - | K7: Average EPS CAGR | L7: 5 Years | M7: =AVERAGE(G9:G30) -> 0.075213377 | P7: 35065 | Q7: 27.3635 | S7: =S6+1 -> 2003 | T7: =AVERAGEIFS($Q$5:$Q$382,$P$5:$P$382,">="&DATE(S7,1,1),$P$5:$P$382,"<="&DATE(S7,12,31)) -> 58.0532
B8: ='DE 40 Historical Data'!B7 -> 2004 | C8: ='DE 40 Historical Data'!C7 -> 3004.65 | D8: =T9 -> 14.09645 | E8: =C8/D8 -> 213.14941 | F8: =_xlfn.RRI(3,E5,E8) -> 0.35209593 | H8: - | I8: - | P8: 35247 | Q8: 25.9702 | S8: =S7+1 -> 2004 | T8: =AVERAGEIFS($Q$5:$Q$382,$P$5:$P$382,">="&DATE(S8,1,1),$P$5:$P$382,"<="&DATE(S8,12,31)) -> 22.7272
B9: ='DE 40 Historical Data'!B8 -> 2005 | C9: ='DE 40 Historical Data'!C8 -> 3719.79 | D9: =T10 -> 12.43145 | E9: =C9/D9 -> 299.22415 | F9: =_xlfn.RRI(3,E6,E9) -> 1.0091667 | G9: =_xlfn.RRI(5,E4,E9) -> 0.01727686 | H9: - | I9: - | K9: Average EPS CAGR | L9: 3 Years | M9: =AVERAGE(F7:F30) -> 0.098959983 | P9: 35431 | Q9: 23.1544 | S9: =S8+1 -> 2005 | T9: =AVERAGEIFS($Q$5:$Q$382,$P$5:$P$382,">="&DATE(S9,1,1),$P$5:$P$382,"<="&DATE(S9,12,31)) -> 14.09645
B10: ='DE 40 Historical Data'!B9 -> 2006 | C10: ='DE 40 Historical Data'!C9 -> 4429.01 | D10: =T11 -> 13.1599 | E10: =C10/D10 -> 336.55347 | F10: =_xlfn.RRI(3,E7,E10) -> 0.38841948 | G10: =_xlfn.RRI(5,E5,E10) -> 0.31304161 | I10: - | P10: 35612 | Q10: 27.1764 | S10: =S9+1 -> 2006 | T10: =AVERAGEIFS($Q$5:$Q$382,$P$5:$P$382,">="&DATE(S10,1,1),$P$5:$P$382,"<="&DATE(S10,12,31)) -> 12.43145
B11: ='DE 40 Historical Data'!B10 -> 2007 | C11: ='DE 40 Historical Data'!C10 -> 5277.23 | D11: =T12 -> 10.3386 | E11: =C11/D11 -> 510.43952 | F11: =_xlfn.RRI(3,E8,E11) -> 0.3378889 | G11: =_xlfn.RRI(5,E6,E11) -> 0.69121616 | H11: =_xlfn.RRI(7,E4,E11) -> 0.092569491 | I11: - | P11: 35796 | Q11: 37.4589 | S11: =S10+1 -> 2007 | T11: =AVERAGEIFS($Q$5:$Q$382,$P$5:$P$382,">="&DATE(S11,1,1),$P$5:$P$382,"<="&DATE(S11,12,31)) -> 13.1599
B12: ='DE 40 Historical Data'!B11 -> 2008 | C12: ='DE 40 Historical Data'!C11 -> 3041.6 | D12: =T13 -> 26.56985 | E12: =C12/D12 -> 114.47562 | F12: =_xlfn.RRI(3,E9,E12) -> -0.2740521 | G12: =_xlfn.RRI(5,E7,E12) -> -0.01860418 | H12: =_xlfn.RRI(7,E5,E12) -> 0.041306952 | I12: - | P12: 35977 | Q12: 19.5084 | S12: =S11+1 -> 2008 | T12: =AVERAGEIFS($Q$5:$Q$382,$P$5:$P$382,">="&DATE(S12,1,1),$P$5:$P$382,"<="&DATE(S12,12,31)) -> 10.3386
B13: ='DE 40 Historical Data'!B12 -> 2009 | C13: ='DE 40 Historical Data'!C12 -> 3604.02 | D13: =T14 -> 14.333 | E13: =C13/D13 -> 251.4491 | F13: =_xlfn.RRI(3,E10,E13) -> -0.092600212 | G13: =_xlfn.RRI(5,E8,E13) -> 0.033601644 | H13: =_xlfn.RRI(7,E6,E13) -> 0.31544177 | P13: 36161 | Q13: 26.1107 | S13: =S12+1 -> 2009 | T13: =AVERAGEIFS($Q$5:$Q$382,$P$5:$P$382,">="&DATE(S13,1,1),$P$5:$P$382,"<="&DATE(S13,12,31)) -> 26.56985
B14: ='DE 40 Historical Data'!B13 -> 2010 | C14: ='DE 40 Historical Data'!C13 -> 4053.71 | D14: =T15 -> 10.8497 | E14: =C14/D14 -> 373.62416 | F14: =_xlfn.RRI(3,E11,E14) -> -0.09878125 | G14: =_xlfn.RRI(5,E9,E14) -> 0.045412437 | H14: =_xlfn.RRI(7,E7,E14) -> 0.16832395 | I14: =_xlfn.RRI(10,E4,E14) -> 0.0312487 | P14: 36342 | Q14: 18.6125 | S14: =S13+1 -> 2010 | T14: =AVERAGEIFS($Q$5:$Q$382,$P$5:$P$382,">="&DATE(S14,1,1),$P$5:$P$382,"<="&DATE(S14,12,31)) -> 14.333
B15: ='DE 40 Historical Data'!B14 -> 2011 | C15: ='DE 40 Historical Data'!C14 -> 3346.06 | D15: =T16 -> 10.53005 | E15: =C15/D15 -> 317.76297 | F15: =_xlfn.RRI(3,E12,E15) -> 0.40538969 | G15: =_xlfn.RRI(5,E10,E15) -> -0.011424498 | H15: =_xlfn.RRI(7,E8,E15) -> 0.058703052 | I15: =_xlfn.RRI(10,E5,E15) -> 0.13931592 | P15: 36526 | Q15: 29.3393 | S15: =S14+1 -> 2011 | T15: =AVERAGEIFS($Q$5:$Q$382,$P$5:$P$382,">="&DATE(S15,1,1),$P$5:$P$382,"<="&DATE(S15,12,31)) -> 10.8497
B16: ='DE 40 Historical Data'!B15 -> 2012 | C16: ='DE 40 Historical Data'!C15 -> 4161.3 | D16: =T17 -> 13.16715 | E16: =C16/D16 -> 316.0365 | F16: =_xlfn.RRI(3,E13,E16) -> 0.079184545 | G16: =_xlfn.RRI(5,E11,E16) -> -0.091429586 | H16: =_xlfn.RRI(7,E9,E16) -> 0.0078398247 | I16: =_xlfn.RRI(10,E6,E16) -> 0.23959226 | P16: 36708 | Q16: 26.0185 | S16: =S15+1 -> 2012 | T16: =AVERAGEIFS($Q$5:$Q$382,$P$5:$P$382,">="&DATE(S16,1,1),$P$5:$P$382,"<="&DATE(S16,12,31)) -> 10.53005
B17: ='DE 40 Historical Data'!B16 -> 2013 | C17: ='DE 40 Historical Data'!C16 -> 5051.89 | D17: =T18 -> 14.76745 | E17: =C17/D17 -> 342.0963 | F17: =_xlfn.RRI(3,E14,E17) -> -0.028958457 | G17: =_xlfn.RRI(5,E12,E17) -> 0.24476416 | H17: =_xlfn.RRI(7,E10,E17) -> 0.0023363308 | I17: =_xlfn.RRI(10,E7,E17) -> 0.10526302 | P17: 36892 | Q17: 17.1739 | S17: =S16+1 -> 2013 | T17: =AVERAGEIFS($Q$5:$Q$382,$P$5:$P$382,">="&DATE(S17,1,1),$P$5:$P$382,"<="&DATE(S17,12,31)) -> 13.16715
B18: ='DE 40 Historical Data'!B17 -> 2014 | C18: ='DE 40 Historical Data'!C17 -> 5044.71 | D18: =T19 -> 15.41425 | E18: =C18/D18 -> 327.27574 | F18: =_xlfn.RRI(3,E15,E18) -> 0.0098809317 | G18: =_xlfn.RRI(5,E13,E18) -> 0.054126529 | H18: =_xlfn.RRI(7,E11,E18) -> -0.06152174 | I18: =_xlfn.RRI(10,E8,E18) -> 0.043813639 | P18: 37073 | Q18: 18.7599 | S18: =S17+1 -> 2014 | T18: =AVERAGEIFS($Q$5:$Q$382,$P$5:$P$382,">="&DATE(S18,1,1),$P$5:$P$382,"<="&DATE(S18,12,31)) -> 14.76745
B19: ='DE 40 Historical Data'!B18 -> 2015 | C19: ='DE 40 Historical Data'!C18 -> 5390.31 | D19: =T20 -> 14.4075 | E19: =C19/D19 -> 374.13222 | F19: =_xlfn.RRI(3,E16,E19) -> 0.057862666 | G19: =_xlfn.RRI(5,E14,E19) -> 0.00027181924 | H19: =_xlfn.RRI(7,E12,E19) -> 0.18433117 | I19: =_xlfn.RRI(10,E9,E19) -> 0.022593076 | P19: 37257 | Q19: 34.7371 | S19: =S18+1 -> 2015 | T19: =AVERAGEIFS($Q$5:$Q$382,$P$5:$P$382,">="&DATE(S19,1,1),$P$5:$P$382,"<="&DATE(S19,12,31)) -> 15.41425
B20: ='DE 40 Historical Data'!B19 -> 2016 | C20: ='DE 40 Historical Data'!C19 -> 5588.27 | D20: =T21 -> 15.87945 | E20: =C20/D20 -> 351.91836 | F20: =_xlfn.RRI(3,E17,E20) -> 0.0094803032 | G20: =_xlfn.RRI(5,E15,E20) -> 0.020628583 | H20: =_xlfn.RRI(7,E13,E20) -> 0.04919443 | I20: =_xlfn.RRI(10,E10,E20) -> 0.0044741977 | P20: 37438 | Q20: 55.4276 | S20: =S19+1 -> 2016 | T20: =AVERAGEIFS($Q$5:$Q$382,$P$5:$P$382,">="&DATE(S20,1,1),$P$5:$P$382,"<="&DATE(S20,12,31)) -> 14.4075
B21: ='DE 40 Historical Data'!B20 -> 2017 | C21: ='DE 40 Historical Data'!C20 -> 6122.26 | D21: =T22 -> 14.4507 | E21: =C21/D21 -> 423.66529 | F21: =_xlfn.RRI(3,E18,E21) -> 0.089857438 | G21: =_xlfn.RRI(5,E16,E21) -> 0.060369258 | H21: =_xlfn.RRI(7,E14,E21) -> 0.018118378 | I21: =_xlfn.RRI(10,E11,E21) -> -0.018460324 | P21: 37622 | Q21: 77.7918 | S21: =S20+1 -> 2017 | T21: =AVERAGEIFS($Q$5:$Q$382,$P$5:$P$382,">="&DATE(S21,1,1),$P$5:$P$382,"<="&DATE(S21,12,31)) -> 15.87945
B22: ='DE 40 Historical Data'!B21 -> 2018 | C22: ='DE 40 Historical Data'!C21 -> 4862.74 | D22: =T23 -> 16.86225 | E22: =C22/D22 -> 288.38026 | F22: =_xlfn.RRI(3,E19,E22) -> -0.08311795 | G22: =_xlfn.RRI(5,E17,E22) -> -0.033585517 | H22: =_xlfn.RRI(7,E15,E22) -> -0.013765208 | I22: =_xlfn.RRI(10,E12,E22) -> 0.096794472 | P22: 37926 | Q22: 38.3146 | S22: =S21+1 -> 2018 | T22: =AVERAGEIFS($Q$5:$Q$382,$P$5:$P$382,">="&DATE(S22,1,1),$P$5:$P$382,"<="&DATE(S22,12,31)) -> 14.4507
B23: ='DE 40 Historical Data'!B22 -> 2019 | C23: ='DE 40 Historical Data'!C22 -> 5909.66 | D23: =T24 -> 20.24445 | E23: =C23/D23 -> 291.91507 | F23: =_xlfn.RRI(3,E20,E23) -> -0.060410411 | G23: =_xlfn.RRI(5,E18,E23) -> -0.022608537 | H23: =_xlfn.RRI(7,E16,E23) -> -0.011278037 | I23: =_xlfn.RRI(10,E13,E23) -> 0.015034122 | P23: 38108 | Q23: 28.7454 | S23: =S22+1 -> 2019 | T23: =AVERAGEIFS($Q$5:$Q$382,$P$5:$P$382,">="&DATE(S23,1,1),$P$5:$P$382,"<="&DATE(S23,12,31)) -> 16.86225
B24: ='DE 40 Historical Data'!B23 -> 2020 | C24: ='DE 40 Historical Data'!C23 -> 5935.22 | D24: =T25 -> 17.41165 | E24: =C24/D24 -> 340.87637 | F24: =_xlfn.RRI(3,E21,E24) -> -0.069910654 | G24: =_xlfn.RRI(5,E19,E24) -> -0.018445642 | H24: =_xlfn.RRI(7,E17,E24) -> -0.00051021595 | I24: =_xlfn.RRI(10,E14,E24) -> -0.0091311067 | P24: 38292 | Q24: 16.709 | S24: =S23+1 -> 2020 | T24: =AVERAGEIFS($Q$5:$Q$382,$P$5:$P$382,">="&DATE(S24,1,1),$P$5:$P$382,"<="&DATE(S24,12,31)) -> 20.24445
B25: ='DE 40 Historical Data'!B24 -> 2021 | C25: ='DE 40 Historical Data'!C24 -> 6709.66 | D25: =T26 -> 11.33715 | E25: =C25/D25 -> 591.82952 | F25: =_xlfn.RRI(3,E22,E25) -> 0.27079949 | G25: =_xlfn.RRI(5,E20,E25) -> 0.10956038 | H25: =_xlfn.RRI(7,E18,E25) -> 0.088315182 | I25: =_xlfn.RRI(10,E15,E25) -> 0.064165887 | P25: 38473 | Q25: 14.8886 | S25: =S24+1 -> 2021 | T25: =AVERAGEIFS($Q$5:$Q$382,$P$5:$P$382,">="&DATE(S25,1,1),$P$5:$P$382,"<="&DATE(S25,12,31)) -> 17.41165
... B29: ='DE 40 Historical Data'!B28 -> 2025 | C29: ='DE 40 Historical Data'!C28 -> 9175.13 | D29: =T30 -> 16.14495 | E29: =C29/D29 -> 568.29721 | F29: =_xlfn.RRI(3,E26,E29) -> 0.088408563 | G29: =_xlfn.RRI(5,E24,E29) -> 0.10763259 | H29: =_xlfn.RRI(7,E22,E29) -> 0.10176036 | I29: =_xlfn.RRI(10,E19,E29) -> 0.042689598 | P29: 39203 | Q29: 13.9396 | S29: =S28+1 -> 2025 | T29: =AVERAGEIFS($Q$5:$Q$382,$P$5:$P$382,">="&DATE(S29,1,1),$P$5:$P$382,"<="&DATE(S29,12,31)) -> 18.82975
B30: ='DE 40 Historical Data'!B29 -> 2026 | C30: ='DE 40 Historical Data'!C29 -> 9337 | D30: =T30 -> 16.14495 | E30: =C30/D30 -> 578.32325 | F30: =_xlfn.RRI(3,E27,E30) -> 0.10711309 | G30: =_xlfn.RRI(5,E25,E30) -> -0.0046064856 | H30: =_xlfn.RRI(7,E23,E30) -> 0.10259573 | I30: =_xlfn.RRI(10,E20,E30) -> 0.050927782 | P30: 39387 | Q30: 12.3802 | S30: =S29+1 -> 2026 | T30: =AVERAGEIFS($Q$5:$Q$382,$P$5:$P$382,">="&DATE(S30,1,1),$P$5:$P$382,"<="&DATE(S30,12,31)) -> 16.14495
P31: 39569 | Q31: 12.4069
P32: 39753 | Q32: 8.2703
P33: 39934 | Q33: 21.2426 | S33: Source | T33: https://en.macromicro.me/series/20704/msci-germany-index-pe-ratio
P34: 40118 | Q34: 31.8971
P35: 40299 | Q35: 15.439
P36: 40483 | Q36: 13.227
P37: 40664 | Q37: 11.5284
P38: 40848 | Q38: 10.171
P39: 41030 | Q39: 10.4484
P40: 41214 | Q40: 10.6117
P41: 41395 | Q41: 11.1711
P42: 41579 | Q42: 15.1632
P43: 41760 | Q43: 15.3368
P44: 41944 | Q44: 14.1981
...

Sheet DE 40 Historical Data
A1: #
B2: Year | C2: DE 40 Kursi Index Average Range | D2: Average Return
B3: 2000 | C3: 4934.85 | F3: CAGR DE 40 Kursindex Returns - | G3: 20 | H3: =_xlfn.RRI(G3,C8,$C$27) -> 0.036699847
B4: 2001 | C4: 3887.48 | D4: =C4/C3-1 -> -0.21223948
B5: 2002 | C5: 2141.78 | D5: =C5/C4-1 -> -0.44905697 | F5: =$F$3 -> CAGR DE 40 Kursindex Returns - | G5: 15 | H5: =_xlfn.RRI(G5,C13,$C$27) -> 0.043234071
B6: 2003 | C6: 2857.84 | D6: =C6/C5-1 -> 0.33432939
B7: 2004 | C7: 3004.65 | D7: =C7/C6-1 -> 0.051370965 | F7: =$F$3 -> CAGR DE 40 Kursindex Returns - | G7: 10 | H7: =_xlfn.RRI(G7,C18,$C$27) -> 0.035610719
B8: 2005 | C8: 3719.79 | D8: =C8/C7-1 -> 0.23801108
B9: 2006 | C9: 4429.01 | D9: =C9/C8-1 -> 0.1906613 | F9: =$F$3 -> CAGR DE 40 Kursindex Returns - | G9: 7 | H9: =_xlfn.RRI(G9,C21,$C$27) -> 0.066841062
B10: 2007 | C10: 5277.23 | D10: =C10/C9-1 -> 0.19151458
B11: 2008 | C11: 3041.6 | D11: =C11/C10-1 -> -0.42363702 | F11: =$F$3 -> CAGR DE 40 Kursindex Returns - | G11: 5 | H11: =_xlfn.RRI(G11,C23,$C$27) -> 0.052030807
B12: 2009 | C12: 3604.02 | D12: =C12/C11-1 -> 0.18490926
B13: 2010 | C13: 4053.71 | D13: =C13/C12-1 -> 0.12477456
B14: 2011 | C14: 3346.06 | D14: =C14/C13-1 -> -0.17456848
B15: 2012 | C15: 4161.3 | D15: =C15/C14-1 -> 0.24364178
B16: 2013 | C16: 5051.89 | D16: =C16/C15-1 -> 0.21401725
B17: 2014 | C17: 5044.71 | D17: =C17/C16-1 -> -0.0014212503
B18: 2015 | C18: 5390.31 | D18: =C18/C17-1 -> 0.068507407
B19: 2016 | C19: 5588.27 | D19: =C19/C18-1 -> 0.036725161
B20: 2017 | C20: 6122.26 | D20: =C20/C19-1 -> 0.095555512
B21: 2018 | C21: 4862.74 | D21: =C21/C20-1 -> -0.20572795
B22: 2019 | C22: 5909.66 | D22: =C22/C21-1 -> 0.21529426
B23: 2020 | C23: 5935.22 | D23: =C23/C22-1 -> 0.0043251219 | H23: MSFT
B24: 2021 | C24: 6709.66 | D24: =C24/C23-1 -> 0.13048211
B25: 2022 | C25: 5692.03 | D25: =C25/C24-1 -> -0.1516664
B26: 2023 | C26: 6628.85 | D26: =C26/C25-1 -> 0.16458452
B27: 2024 | C27: 7648.55 | D27: =C27/C26-1 -> 0.15382759
B28: 2025 | C28: 9175.13 | D28: =C28/C27-1 -> 0.19959077
B29: 2026 | C29: 9337 | D29: =C29/C28-1 -> 0.017642257
B31: Source
B32: https://www.boerse.de/historische-kurse-jahre/DAX-Kursindex/DE0008467440

Sheet DE 40 Perf Historical Data
A1: #
B2: Date | C2: Price | D2: Change % | G2: Year | H2: DE 40 Performance Index Average Range | I2: Average Return
B3: 35797 | C3: 4364.32 | G3: 2001 | H3: =_xlfn.MAXIFS($C$3:$C$6983,$B$3:$B$6983,">="&DATE(G3,12,28),$B$3:$B$6983,"<="&DATE(G3,12,31)) -> 5160.1
B4: 35800 | C4: 4416.95 | D4: =C4/C3-1 -> 0.012059152 | G4: =G3+1 -> 2002 | H4: =_xlfn.MAXIFS($C$3:$C$6983,$B$3:$B$6983,">="&DATE(G4,12,28),$B$3:$B$6983,"<="&DATE(G4,12,31)) -> 2892.63 | I4: =H4/H3-1 -> -0.43942365 | K4: CAGR DE 40 Performance Returns - | L4: 20 | M4: =_xlfn.RRI(L4,H8,$H$27) -> 0.067661997
B5: 35801 | C5: 4360.05 | D5: =C5/C4-1 -> -0.012882192 | G5: =G4+1 -> 2003 | H5: =_xlfn.MAXIFS($C$3:$C$6983,$B$3:$B$6983,">="&DATE(G5,12,28),$B$3:$B$6983,"<="&DATE(G5,12,31)) -> 3965.16 | I5: =H5/H4-1 -> 0.37078022
B6: 35802 | C6: 4339.98 | D6: =C6/C5-1 -> -0.0046031582 | G6: =G5+1 -> 2004 | H6: =_xlfn.MAXIFS($C$3:$C$6983,$B$3:$B$6983,">="&DATE(G6,12,28),$B$3:$B$6983,"<="&DATE(G6,12,31)) -> 4261.79 | I6: =H6/H5-1 -> 0.074809087 | K6: =$K$4 -> CAGR DE 40 Performance Returns - | L6: 15 | M6: =_xlfn.RRI(L6,H13,$H$27) -> 0.099556882
B7: 35803 | C7: 4293.64 | D7: =C7/C6-1 -> -0.010677469 | G7: =G6+1 -> 2005 | H7: =_xlfn.MAXIFS($C$3:$C$6983,$B$3:$B$6983,">="&DATE(G7,12,28),$B$3:$B$6983,"<="&DATE(G7,12,31)) -> 5458.58 | I7: =H7/H6-1 -> 0.28081862
B8: 35804 | C8: 4237.75 | D8: =C8/C7-1 -> -0.013016927 | G8: =G7+1 -> 2006 | H8: =_xlfn.MAXIFS($C$3:$C$6983,$B$3:$B$6983,">="&DATE(G8,12,28),$B$3:$B$6983,"<="&DATE(G8,12,31)) -> 6611.81 | I8: =H8/H7-1 -> 0.21126923 | K8: =$K$4 -> CAGR DE 40 Performance Returns - | L8: 10 | M8: =_xlfn.RRI(L8,H18,$H$27) -> 0.078701809
B9: 35807 | C9: 4134.64 | D9: =C9/C8-1 -> -0.024331308 | G9: =G8+1 -> 2007 | H9: =_xlfn.MAXIFS($C$3:$C$6983,$B$3:$B$6983,">="&DATE(G9,12,28),$B$3:$B$6983,"<="&DATE(G9,12,31)) -> 8067.32 | I9: =H9/H8-1 -> 0.2201379
B10: 35808 | C10: 4150.01 | D10: =C10/C9-1 -> 0.0037173732 | G10: =G9+1 -> 2008 | H10: =_xlfn.MAXIFS($C$3:$C$6983,$B$3:$B$6983,">="&DATE(G10,12,28),$B$3:$B$6983,"<="&DATE(G10,12,31)) -> 4810.2 | I10: =H10/H9-1 -> -0.40374251 | K10: =$K$4 -> CAGR DE 40 Performance Returns - | L10: 7 | M10: =_xlfn.RRI(L10,H21,$H$27) -> 0.091732124
B11: 35809 | C11: 4145.41 | D11: =C11/C10-1 -> -0.0011084311 | G11: =G10+1 -> 2009 | H11: =_xlfn.MAXIFS($C$3:$C$6983,$B$3:$B$6983,">="&DATE(G11,12,28),$B$3:$B$6983,"<="&DATE(G11,12,31)) -> 6011.55 | I11: =H11/H10-1 -> 0.24975053
B12: 35810 | C12: 4140.22 | D12: =C12/C11-1 -> -0.0012519871 | G12: =G11+1 -> 2010 | H12: =_xlfn.MAXIFS($C$3:$C$6983,$B$3:$B$6983,">="&DATE(G12,12,28),$B$3:$B$6983,"<="&DATE(G12,12,31)) -> 6995.47 | I12: =H12/H11-1 -> 0.1636716 | K12: =$K$4 -> CAGR DE 40 Performance Returns - | L12: 5 | M12: =_xlfn.RRI(L12,H23,$H$27) -> 0.089362697
B13: 35811 | C13: 4216.24 | D13: =C13/C12-1 -> 0.018361343 | G13: =G12+1 -> 2011 | H13: =_xlfn.MAXIFS($C$3:$C$6983,$B$3:$B$6983,">="&DATE(G13,12,28),$B$3:$B$6983,"<="&DATE(G13,12,31)) -> 5898.35 | I13: =H13/H12-1 -> -0.15683292
B14: 35814 | C14: 4290.05 | D14: =C14/C13-1 -> 0.017506119 | G14: =G13+1 -> 2012 | H14: =_xlfn.MAXIFS($C$3:$C$6983,$B$3:$B$6983,">="&DATE(G14,12,28),$B$3:$B$6983,"<="&DATE(G14,12,31)) -> 7612.39 | I14: =H14/H13-1 -> 0.29059652
B15: 35815 | C15: 4310.83 | D15: =C15/C14-1 -> 0.0048437664 | G15: =G14+1 -> 2013 | H15: =_xlfn.MAXIFS($C$3:$C$6983,$B$3:$B$6983,">="&DATE(G15,12,28),$B$3:$B$6983,"<="&DATE(G15,12,31)) -> 9552.16 | I15: =H15/H14-1 -> 0.25481748
B16: 35816 | C16: 4250.47 | D16: =C16/C15-1 -> -0.014001944 | G16: =G15+1 -> 2014 | H16: =_xlfn.MAXIFS($C$3:$C$6983,$B$3:$B$6983,">="&DATE(G16,12,28),$B$3:$B$6983,"<="&DATE(G16,12,31)) -> 9927.13 | I16: =H16/H15-1 -> 0.039254996
B17: 35817 | C17: 4238.77 | D17: =C17/C16-1 -> -0.0027526368 | G17: =G16+1 -> 2015 | H17: =_xlfn.MAXIFS($C$3:$C$6983,$B$3:$B$6983,">="&DATE(G17,12,28),$B$3:$B$6983,"<="&DATE(G17,12,31)) -> 10860.14 | I17: =H17/H16-1 -> 0.093985875
B18: 35818 | C18: 4222.16 | D18: =C18/C17-1 -> -0.0039185896 | G18: =G17+1 -> 2016 | H18: =_xlfn.MAXIFS($C$3:$C$6983,$B$3:$B$6983,">="&DATE(G18,12,28),$B$3:$B$6983,"<="&DATE(G18,12,31)) -> 11481.06 | I18: =H18/H17-1 -> 0.057174217
B19: 35821 | C19: 4266.34 | D19: =C19/C18-1 -> 0.010463838 | G19: =G18+1 -> 2017 | H19: =_xlfn.MAXIFS($C$3:$C$6983,$B$3:$B$6983,">="&DATE(G19,12,28),$B$3:$B$6983,"<="&DATE(G19,12,31)) -> 12979.94 | I19: =H19/H18-1 -> 0.13055241
B20: 35822 | C20: 4316.05 | D20: =C20/C19-1 -> 0.011651673 | G20: =G19+1 -> 2018 | H20: =_xlfn.MAXIFS($C$3:$C$6983,$B$3:$B$6983,">="&DATE(G20,12,28),$B$3:$B$6983,"<="&DATE(G20,12,31)) -> 10558.96 | I20: =H20/H19-1 -> -0.18651704
B21: 35823 | C21: 4385.29 | D21: =C21/C20-1 -> 0.016042446 | G21: =G20+1 -> 2019 | H21: =_xlfn.MAXIFS($C$3:$C$6983,$B$3:$B$6983,">="&DATE(G21,12,28),$B$3:$B$6983,"<="&DATE(G21,12,31)) -> 13249.01 | I21: =H21/H20-1 -> 0.25476467
B22: 35824 | C22: 4444.53 | D22: =C22/C21-1 -> 0.013508799 | G22: =G21+1 -> 2020 | H22: =_xlfn.MAXIFS($C$3:$C$6983,$B$3:$B$6983,">="&DATE(G22,12,28),$B$3:$B$6983,"<="&DATE(G22,12,31)) -> 13790.29 | I22: =H22/H21-1 -> 0.040854373
B23: 35825 | C23: 4442.53 | D23: =C23/C22-1 -> -0.00044999134 | G23: =G22+1 -> 2021 | H23: =_xlfn.MAXIFS($C$3:$C$6983,$B$3:$B$6983,">="&DATE(G23,12,28),$B$3:$B$6983,"<="&DATE(G23,12,31)) -> 15963.7 | I23: =H23/H22-1 -> 0.15760437
B24: 35828 | C24: 4529.88 | D24: =C24/C23-1 -> 0.01966222 | G24: =G23+1 -> 2022 | H24: =_xlfn.MAXIFS($C$3:$C$6983,$B$3:$B$6983,">="&DATE(G24,12,28),$B$3:$B$6983,"<="&DATE(G24,12,31)) -> 14071.72 | I24: =H24/H23-1 -> -0.11851764 | M24: MSFT
B25: 35829 | C25: 4529.18 | D25: =C25/C24-1 -> -0.00015452948 | G25: =G24+1 -> 2023 | H25: =_xlfn.MAXIFS($C$3:$C$6983,$B$3:$B$6983,">="&DATE(G25,12,28),$B$3:$B$6983,"<="&DATE(G25,12,31)) -> 16751.64 | I25: =H25/H24-1 -> 0.19044722
B26: 35830 | C26: 4509.25 | D26: =C26/C25-1 -> -0.004400355 | G26: =G25+1 -> 2024 | H26: =_xlfn.MAXIFS($C$3:$C$6983,$B$3:$B$6983,">="&DATE(G26,12,28),$B$3:$B$6983,"<="&DATE(G26,12,31)) -> 19909.14 | I26: =H26/H25-1 -> 0.18848901
B27: 35831 | C27: 4494.72 | D27: =C27/C26-1 -> -0.0032222653 | G27: =G26+1 -> 2025 | H27: =_xlfn.MAXIFS($C$3:$C$6983,$B$3:$B$6983,">="&DATE(G27,12,28),$B$3:$B$6983,"<="&DATE(G27,12,31)) -> 24490.41 | I27: =H27/H26-1 -> 0.23010888
B28: 35832 | C28: 4536.91 | D28: =C28/C27-1 -> 0.0093865691
B29: 35835 | C29: 4519.56 | D29: =C29/C28-1 -> -0.0038241887
B30: 35836 | C30: 4558.62 | D30: =C30/C29-1 -> 0.0086424342
B31: 35837 | C31: 4552.46 | D31: =C31/C30-1 -> -0.0013512861
B32: 35838 | C32: 4509.37 | D32: =C32/C31-1 -> -0.0094652122
B33: 35839 | C33: 4522.42 | D33: =C33/C32-1 -> 0.0028939741
B34: 35842 | C34: 4535.56 | D34: =C34/C33-1 -> 0.002905524
B35: 35843 | C35: 4627.42 | D35: =C35/C34-1 -> 0.020253287
B36: 35844 | C36: 4611.66 | D36: =C36/C35-1 -> -0.0034057855
B37: 35845 | C37: 4581.08 | D37: =C37/C36-1 -> -0.0066310179
B38: 35846 | C38: 4583.03 | D38: =C38/C37-1 -> 0.00042566382
B39: 35849 | C39: 4610.66 | D39: =C39/C38-1 -> 0.0060287626
... B6983: 46203 | C6983: 24930.18 | D6983: =C6983/C6982-1 -> 0.0123154

Sheet Risk Free Rate Calculation
A1: # | B1: 10Y Germany Bond Historical Data
B3: Date | C3: Yield | D3: Open | E3: High | F3: Low | G3: Change % | I3: Year | J3: 10Y Bond Average Range | L3: Average Rate | M3: 20 years | N3: =AVERAGE(J12:J31) -> 0.016721806 | P3: Risk Free Rate using CDS Approach
B4: 36162 | C4: 0.03863 | D4: 0.03863 | E4: 0.03863 | F4: 0.03863 | G4: 0 | I4: 1999 | J4: =AVERAGEIFS($C$4:$C$7448,$B$4:$B$7448,">="&DATE(I4,1,1),$B$4:$B$7448,"<="&DATE(I4,12,31)) -> 0.045185119 | P4: Government Bond Rate | S4: =C7448 -> 0.030376
B5: 36163 | C5: 0.03863 | D5: 0.03863 | E5: 0.03863 | F5: 0.03863 | G5: 0 | I5: =I4+1 -> 2000 | J5: =AVERAGEIFS($C$4:$C$7448,$B$4:$B$7448,">="&DATE(I5,1,1),$B$4:$B$7448,"<="&DATE(I5,12,31)) -> 0.052646361 | L5: Average Rate | M5: 15 years | N5: =AVERAGE(J17:J31) -> 0.011005388 | P5: Country Default Swap Rate | S5: ='[1]Risk Free Rate Calculation'!$G$57 -> 0.0021 | U5: as on 01-04-2026
B6: 36164 | C6: 0.03748 | D6: 0.03748 | E6: 0.03748 | F6: 0.03748 | G6: -0.0298 | I6: =I5+1 -> 2001 | J6: =AVERAGEIFS($C$4:$C$7448,$B$4:$B$7448,">="&DATE(I6,1,1),$B$4:$B$7448,"<="&DATE(I6,12,31)) -> 0.048165078 | P6: Risk Free Rate using CDS Approach | S6: =S4-S5 -> 0.028276
B7: 36165 | C7: 0.03791 | D7: 0.03791 | E7: 0.03791 | F7: 0.03791 | G7: 0.0115 | I7: =I6+1 -> 2002 | J7: =AVERAGEIFS($C$4:$C$7448,$B$4:$B$7448,">="&DATE(I7,1,1),$B$4:$B$7448,"<="&DATE(I7,12,31)) -> 0.047922654 | L7: Average Rate | M7: 10 years | N7: =AVERAGE(J22:J31) -> 0.011405122
B8: 36166 | C8: 0.03768 | D8: 0.03768 | E8: 0.03768 | F8: 0.03768 | G8: -0.0061 | I8: =I7+1 -> 2003 | J8: =AVERAGEIFS($C$4:$C$7448,$B$4:$B$7448,">="&DATE(I8,1,1),$B$4:$B$7448,"<="&DATE(I8,12,31)) -> 0.040877704
B9: 36167 | C9: 0.03711 | D9: 0.03711 | E9: 0.03711 | F9: 0.03711 | G9: -0.0151 | I9: =I8+1 -> 2004 | J9: =AVERAGEIFS($C$4:$C$7448,$B$4:$B$7448,">="&DATE(I9,1,1),$B$4:$B$7448,"<="&DATE(I9,12,31)) -> 0.040620965 | L9: Average Rate | M9: 7 years | N9: =AVERAGE(J25:J31) -> 0.015395512
B10: 36168 | C10: 0.03714 | D10: 0.03714 | E10: 0.03714 | F10: 0.03714 | G10: 0.0008 | I10: =I9+1 -> 2005 | J10: =AVERAGEIFS($C$4:$C$7448,$B$4:$B$7448,">="&DATE(I10,1,1),$B$4:$B$7448,"<="&DATE(I10,12,31)) -> 0.033802394
B11: 36171 | C11: 0.03724 | D11: 0.03724 | E11: 0.03724 | F11: 0.03724 | G11: 0.0027 | I11: =I10+1 -> 2006 | J11: =AVERAGEIFS($C$4:$C$7448,$B$4:$B$7448,">="&DATE(I11,1,1),$B$4:$B$7448,"<="&DATE(I11,12,31)) -> 0.037722235 | L11: Average Rate | M11: 5 years | N11: =AVERAGE(J27:J31) -> 0.023117104
B12: 36172 | C12: 0.03805 | D12: 0.03805 | E12: 0.03805 | F12: 0.03805 | G12: 0.0218 | I12: =I11+1 -> 2007 | J12: =AVERAGEIFS($C$4:$C$7448,$B$4:$B$7448,">="&DATE(I12,1,1),$B$4:$B$7448,"<="&DATE(I12,12,31)) -> 0.042301667
B13: 36173 | C13: 0.03672 | D13: 0.03672 | E13: 0.03672 | F13: 0.03672 | G13: -0.035 | I13: =I12+1 -> 2008 | J13: =AVERAGEIFS($C$4:$C$7448,$B$4:$B$7448,">="&DATE(I13,1,1),$B$4:$B$7448,"<="&DATE(I13,12,31)) -> 0.040154882 | L13: Average Rate | M13: Latest | N13: =J31 -> 0.029300652
B14: 36174 | C14: 0.03712 | D14: 0.03712 | E14: 0.03712 | F14: 0.03712 | G14: 0.0109 | I14: =I13+1 -> 2009 | J14: =AVERAGEIFS($C$4:$C$7448,$B$4:$B$7448,">="&DATE(I14,1,1),$B$4:$B$7448,"<="&DATE(I14,12,31)) -> 0.032687244
B15: 36175 | C15: 0.03677 | D15: 0.03677 | E15: 0.03677 | F15: 0.03677 | G15: -0.0094 | I15: =I14+1 -> 2010 | J15: =AVERAGEIFS($C$4:$C$7448,$B$4:$B$7448,">="&DATE(I15,1,1),$B$4:$B$7448,"<="&DATE(I15,12,31)) -> 0.027734297 | L15: Dynamic Rate | M15: Risk free rate using CDS Approach | N15: =S6 -> 0.028276
B16: 36176 | C16: 0.03683 | D16: 0.03683 | E16: 0.03683 | F16: 0.03683 | G16: 0.0016 | I16: =I15+1 -> 2011 | J16: =AVERAGEIFS($C$4:$C$7448,$B$4:$B$7448,">="&DATE(I16,1,1),$B$4:$B$7448,"<="&DATE(I16,12,31)) -> 0.026477198
B17: 36177 | C17: 0.03695 | D17: 0.03695 | E17: 0.03695 | F17: 0.03695 | G17: 0.0033 | I17: =I16+1 -> 2012 | J17: =AVERAGEIFS($C$4:$C$7448,$B$4:$B$7448,">="&DATE(I17,1,1),$B$4:$B$7448,"<="&DATE(I17,12,31)) -> 0.015667559
B18: 36178 | C18: 0.03663 | D18: 0.03663 | E18: 0.03663 | F18: 0.03663 | G18: -0.0087 | I18: =I17+1 -> 2013 | J18: =AVERAGEIFS($C$4:$C$7448,$B$4:$B$7448,">="&DATE(I18,1,1),$B$4:$B$7448,"<="&DATE(I18,12,31)) -> 0.016396447
B19: 36179 | C19: 0.03657 | D19: 0.03657 | E19: 0.03657 | F19: 0.03657 | G19: -0.0016 | I19: =I18+1 -> 2014 | J19: =AVERAGEIFS($C$4:$C$7448,$B$4:$B$7448,">="&DATE(I19,1,1),$B$4:$B$7448,"<="&DATE(I19,12,31)) -> 0.012252214
B20: 36180 | C20: 0.03678 | D20: 0.03678 | E20: 0.03678 | F20: 0.03678 | G20: 0.0057 | I20: =I19+1 -> 2015 | J20: =AVERAGEIFS($C$4:$C$7448,$B$4:$B$7448,">="&DATE(I20,1,1),$B$4:$B$7448,"<="&DATE(I20,12,31)) -> 0.0053540035
B21: 36181 | C21: 0.03673 | D21: 0.03673 | E21: 0.03673 | F21: 0.03673 | G21: -0.0014 | I21: =I20+1 -> 2016 | J21: =AVERAGEIFS($C$4:$C$7448,$B$4:$B$7448,">="&DATE(I21,1,1),$B$4:$B$7448,"<="&DATE(I21,12,31)) -> 0.0013593764
B22: 36182 | C22: 0.03648 | D22: 0.03648 | E22: 0.03648 | F22: 0.03648 | G22: -0.0068 | I22: =I21+1 -> 2017 | J22: =AVERAGEIFS($C$4:$C$7448,$B$4:$B$7448,">="&DATE(I22,1,1),$B$4:$B$7448,"<="&DATE(I22,12,31)) -> 0.0037648736
B23: 36185 | C23: 0.03629 | D23: 0.03629 | E23: 0.03629 | F23: 0.03629 | G23: -0.0052 | I23: =I22+1 -> 2018 | J23: =AVERAGEIFS($C$4:$C$7448,$B$4:$B$7448,">="&DATE(I23,1,1),$B$4:$B$7448,"<="&DATE(I23,12,31)) -> 0.0046069708
B24: 36187 | C24: 0.03662 | D24: 0.03662 | E24: 0.03662 | F24: 0.03662 | G24: 0.0091 | I24: =I23+1 -> 2019 | J24: =AVERAGEIFS($C$4:$C$7448,$B$4:$B$7448,">="&DATE(I24,1,1),$B$4:$B$7448,"<="&DATE(I24,12,31)) -> -0.0020892086
B25: 36188 | C25: 0.03645 | D25: 0.03645 | E25: 0.03645 | F25: 0.03645 | G25: -0.0046 | I25: =I24+1 -> 2020 | J25: =AVERAGEIFS($C$4:$C$7448,$B$4:$B$7448,">="&DATE(I25,1,1),$B$4:$B$7448,"<="&DATE(I25,12,31)) -> -0.0047673872
B26: 36189 | C26: 0.03637 | D26: 0.03637 | E26: 0.03637 | F26: 0.03637 | G26: -0.0022 | I26: =I25+1 -> 2021 | J26: =AVERAGEIFS($C$4:$C$7448,$B$4:$B$7448,">="&DATE(I26,1,1),$B$4:$B$7448,"<="&DATE(I26,12,31)) -> -0.0030495438
B27: 36190 | C27: 0.03635 | D27: 0.03635 | E27: 0.03635 | F27: 0.03635 | G27: -0.0005 | I27: =I26+1 -> 2022 | J27: =AVERAGEIFS($C$4:$C$7448,$B$4:$B$7448,">="&DATE(I27,1,1),$B$4:$B$7448,"<="&DATE(I27,12,31)) -> 0.012038801
... B31: 36194 | C31: 0.0375 | D31: 0.0375 | E31: 0.0375 | F31: 0.0375 | G31: 0.0108 | I31: =I30+1 -> 2026 | J31: =AVERAGEIFS($C$4:$C$7448,$B$4:$B$7448,">="&DATE(I31,1,1),$B$4:$B$7448,"<="&DATE(I31,12,31)) -> 0.029300652
B32: 36195 | C32: 0.03822 | D32: 0.03822 | E32: 0.03822 | F32: 0.03822 | G32: 0.0192
B33: 36196 | C33: 0.03776 | D33: 0.03776 | E33: 0.03776 | F33: 0.03776 | G33: -0.012 | I33: Source: Investing.com
B34: 36197 | C34: 0.03781 | D34: 0.03781 | E34: 0.03781 | F34: 0.03781 | G34: 0.0013
B35: 36199 | C35: 0.03855 | D35: 0.03855 | E35: 0.03855 | F35: 0.03855 | G35: 0.0196
B36: 36200 | C36: 0.03787 | D36: 0.03787 | E36: 0.03787 | F36: 0.03787 | G36: -0.0176
B37: 36201 | C37: 0.0379 | D37: 0.0379 | E37: 0.0379 | F37: 0.0379 | G37: 0.0008
B38: 36202 | C38: 0.03805 | D38: 0.03805 | E38: 0.03805 | F38: 0.03805 | G38: 0.004
B39: 36203 | C39: 0.03841 | D39: 0.03841 | E39: 0.03841 | F39: 0.03841 | G39: 0.0095
B40: 36204 | C40: 0.03865 | D40: 0.03865 | E40: 0.03865 | F40: 0.03865 | G40: 0.0062
B41: 36206 | C41: 0.03926 | D41: 0.03926 | E41: 0.03926 | F41: 0.03926 | G41: 0.0158
B42: 36207 | C42: 0.0388 | D42: 0.0388 | E42: 0.0388 | F42: 0.0388 | G42: -0.0117
B43: 36208 | C43: 0.03893 | D43: 0.03893 | E43: 0.03893 | F43: 0.03893 | G43: 0.0034
B44: 36209 | C44: 0.03884 | D44: 0.03884 | E44: 0.03884 | F44: 0.03884 | G44: -0.0023
...

Sheet ERP Historical Data
B2: Date | C2: Equity Risk Premium (%)
B3: 36237 | C3: 0.04348
B4: 36265 | C4: 0.04065
B5: 36300 | C5: 0.03216
B6: 36328 | C6: 0.02723
B7: 36356 | C7: 0.0211
B8: 36391 | C8: 0.02301 | E8: Source: | F8: https://www.market-risk-premia.com/de.html
B9: 36419 | C9: 0.01978
B10: 36447 | C10: 0.01978 | E10: Average ERP | F10: 20 years | G10: =AVERAGE(C75:C327) -> 0.067305601
B11: 36482 | C11: 0.01825
B12: 36510 | C12: 0.01553 | E12: Average ERP | F12: 15 years | G12: =AVERAGE(C148:C327) -> 0.071386817
B13: 36545 | C13: 0.009518
B14: 36573 | C14: 0.00893 | E14: Average ERP | F14: 10 years | G14: =AVERAGE(C208:C327) -> 0.070260809
B15: 36601 | C15: 0.009705
B16: 36636 | C16: 0.01228 | E16: Average ERP | F16: 7 years | G16: =AVERAGE(C243:C327) -> 0.069163496
B17: 36664 | C17: 0.01091
B18: 36692 | C18: 0.01215 | E18: Average ERP | F18: 5 years | G18: =AVERAGE(C267:C327) -> 0.06495733
B19: 36727 | C19: 0.01157
B20: 36755 | C20: 0.01363 | E20: Average ERP | F20: Latest | G20: =C327 -> 0.05415361
B21: 36783 | C21: 0.01406
B22: 36818 | C22: 0.0166
B23: 36846 | C23: 0.01577
B24: 36874 | C24: 0.0164
B25: 36909 | C25: 0.01819
B26: 36937 | C26: 0.01578
B27: 36965 | C27: 0.02257
B28: 37000 | C28: 0.02902
B29: 37028 | C29: 0.02787
B30: 37056 | C30: 0.02813
B31: 37091 | C31: 0.03009
B32: 37119 | C32: 0.03013
... B327: 46112 | C327: 0.05415361

Sheet Dividend Payout Ratio 2025 - 26
A1: #
B2: Industry name | C2: Number of firms | D2: Dividends | E2: Dividends + Buybacks | F2: BuyBacks | G2: Buyback as % of Dividend
B3: Advertising | C3: 88 | D3: 1932.8385 | E3: 3077.17 | F3: =IF(E3>D3,(E3-D3),0) -> 1144.3315 | G3: =F3/D3 -> 0.59204714
B4: Aerospace/Defense | C4: 67 | D4: 6637.3575 | E4: 10200.005 | F4: =IF(E4>D4,(E4-D4),0) -> 3562.6475 | G4: =F4/D4 -> 0.53675691
B5: Air Transport | C5: 33 | D5: 3599.5569 | E5: 4566.371 | F5: =IF(E5>D5,(E5-D5),0) -> 966.8141 | G5: =F5/D5 -> 0.26859253
B6: Apparel | C6: 107 | D6: 18732.504 | E6: 20297.028 | F6: =IF(E6>D6,(E6-D6),0) -> 1564.5242 | G6: =F6/D6 -> 0.083519225
B7: Auto & Truck | C7: 32 | D7: 19517.7 | E7: 31488.92 | F7: =IF(E7>D7,(E7-D7),0) -> 11971.22 | G7: =F7/D7 -> 0.61335198
B8: Auto Parts | C8: 60 | D8: 2141.4086 | E8: 7805.691 | F8: =IF(E8>D8,(E8-D8),0) -> 5664.2824 | G8: =F8/D8 -> 2.6451199
B9: Bank (Money Center) | C9: 114 | D9: 86808.725 | E9: 48894.617 | F9: =IF(E9>D9,(E9-D9),0) -> 0 | G9: =F9/D9 -> 0
B10: Banks (Regional) | C10: 73 | D10: 2395.9139 | E10: 1526.841 | F10: =IF(E10>D10,(E10-D10),0) -> 0 | G10: =F10/D10 -> 0
B11: Beverage (Alcoholic) | C11: 50 | D11: 6931.9168 | E11: 8947.945 | F11: =IF(E11>D11,(E11-D11),0) -> 2016.0282 | G11: =F11/D11 -> 0.29083272
B12: Beverage (Soft) | C12: 15 | D12: 1539.27 | E12: 1791.4 | F12: =IF(E12>D12,(E12-D12),0) -> 252.13 | G12: =F12/D12 -> 0.16379842 | K12: Sector Wise Weights under DE 40
B13: Broadcasting | C13: 21 | D13: 1341.8465 | E13: 1458.369 | F13: =IF(E13>D13,(E13-D13),0) -> 116.5225 | G13: =F13/D13 -> 0.086837429 | K13: Sector | L13: Weights
B14: Brokerage & Investment Banking | C14: 75 | D14: 1401.9417 | E14: 1843.935 | F14: =IF(E14>D14,(E14-D14),0) -> 441.99334 | G14: =F14/D14 -> 0.31527228 | K14: Industrial | L14: 0.1733
B15: Building Materials | C15: 88 | D15: 5356.0547 | E15: 9666.786 | F15: =IF(E15>D15,(E15-D15),0) -> 4310.7313 | G15: =F15/D15 -> 0.80483332 | K15: Chemicals | L15: 0.1524 | N15: Average buyback as a % of Dividend
B16: Business & Consumer Services | C16: 183 | D16: 6383.3046 | E16: 10311.512 | F16: =IF(E16>D16,(E16-D16),0) -> 3928.2074 | G16: =F16/D16 -> 0.61538774 | K16: Insurance | L16: 0.115 | N16: Average buyback as a % of Dividend | O16: =SUMPRODUCT(N28:N121,O28:O121) -> 0.7293616
B17: Cable TV | C17: 3 | D17: 1.07 | E17: 1.07 | F17: =IF(E17>D17,(E17-D17),0) -> 0 | G17: =F17/D17 -> 0 | K17: Automobile | L17: 0.1076
B18: Chemical (Basic) | C18: 62 | D18: 267.185 | E18: 179.921 | F18: =IF(E18>D18,(E18-D18),0) -> 0 | G18: =F18/D18 -> 0 | K18: Pharma & Healthcare | L18: 0.1037
B19: Chemical (Diversified) | C19: 7 | D19: 4028.3 | E19: 5012.6 | F19: =IF(E19>D19,(E19-D19),0) -> 984.3 | G19: =F19/D19 -> 0.24434625 | K19: Software | L19: 0.0847
B20: Chemical (Specialty) | C20: 98 | D20: 10094.65 | E20: 15848.775 | F20: =IF(E20>D20,(E20-D20),0) -> 5754.1245 | G20: =F20/D20 -> 0.57001721 | K20: Telecommunication | L20: 0.0553
B21: Coal & Related Energy | C21: 14 | D21: 81.919 | E21: 35.344 | F21: =IF(E21>D21,(E21-D21),0) -> 0 | G21: =F21/D21 -> 0 | K21: Others | L21: 0.208
B22: Computer Services | C22: 213 | D22: 5680.9384 | E22: 11890.389 | F22: =IF(E22>D22,(E22-D22),0) -> 6209.4507 | G22: =F22/D22 -> 1.0930326
B23: Computers/Peripherals | C23: 42 | D23: 269.2748 | E23: 877.904 | F23: =IF(E23>D23,(E23-D23),0) -> 608.6292 | G23: =F23/D23 -> 2.2602531
B24: Construction Supplies | C24: 118 | D24: 11719.379 | E24: 16587.813 | F24: =IF(E24>D24,(E24-D24),0) -> 4868.4341 | G24: =F24/D24 -> 0.41541742
B25: Diversified | C25: 72 | D25: 9906.1338 | E25: 13362.528 | F25: =IF(E25>D25,(E25-D25),0) -> 3456.3942 | G25: =F25/D25 -> 0.34891455
B26: Drugs (Biotechnology) | C26: 219 | D26: 118.66 | E26: 1840.515 | F26: =IF(E26>D26,(E26-D26),0) -> 1721.855 | G26: =F26/D26 -> 14.510829
B27: Drugs (Pharmaceutical) | C27: 123 | D27: 34041.097 | E27: 46443.833 | F27: =IF(E27>D27,(E27-D27),0) -> 12402.736 | G27: =F27/D27 -> 0.36434595 | K27: Sector Under DE40 | L27: Industry | M27: Buyback as % of dividend | N27: Trimmed Mean Buyback as % of Dividend | O27: Weight under DE40
B28: Education | C28: 20 | D28: 250.61744 | E28: 922.097 | F28: =IF(E28>D28,(E28-D28),0) -> 671.47956 | G28: =F28/D28 -> 2.679301 | K28: Automobile | L28: Auto & Truck | M28: {=_xlfn.XLOOKUP(L28,$B$2:B98,$G$2:G98)} -> 0.61335198 | N28: =TRIMMEAN(M28:M30,0.05) -> 1.1337719 | O28: =VLOOKUP(K28,$K$13:$L$21,2,TRUE) -> 0.1076
B29: Electrical Equipment | C29: 151 | D29: 7266.6817 | E29: 11400.366 | F29: =IF(E29>D29,(E29-D29),0) -> 4133.6843 | G29: =F29/D29 -> 0.56885445 | L29: Auto Parts | M29: {=_xlfn.XLOOKUP(L29,$B$2:B99,$G$2:G99)} -> 2.6451199
B30: Electronics (Consumer & Office) | C30: 20 | D30: 600.232 | E30: 683.656 | F30: =IF(E30>D30,(E30-D30),0) -> 83.424 | G30: =F30/D30 -> 0.13898626 | L30: Rubber& Tires | M30: {=_xlfn.XLOOKUP(L30,$B$2:B100,$G$2:G100)} -> 0.14284387
B31: Electronics (General) | C31: 151 | D31: 2071.8273 | E31: 4361.138 | F31: =IF(E31>D31,(E31-D31),0) -> 2289.3107 | G31: =F31/D31 -> 1.1049718 | K31: Chemicals | L31: Chemical (Basic) | M31: {=_xlfn.XLOOKUP(L31,$B$2:B101,$G$2:G101)} -> 0 | N31: =TRIMMEAN(M31:M33,0.05) -> 0.27145449 | O31: =L15 -> 0.1524
B32: Engineering/Construction | C32: 158 | D32: 8409.8534 | E32: 12033.324 | F32: =IF(E32>D32,(E32-D32),0) -> 3623.4706 | G32: =F32/D32 -> 0.43086013 | L32: Chemical (Diversified) | M32: {=_xlfn.XLOOKUP(L32,$B$2:B102,$G$2:G102)} -> 0.24434625
B33: Entertainment | C33: 201 | D33: 2054.8639 | E33: 2513.593 | F33: =IF(E33>D33,(E33-D33),0) -> 458.7291 | G33: =F33/D33 -> 0.22324062 | L33: Chemical (Specialty) | M33: {=_xlfn.XLOOKUP(L33,$B$2:B103,$G$2:G103)} -> 0.57001721
B34: Environmental & Waste Services | C34: 51 | D34: 558.0947 | E34: 804.706 | F34: =IF(E34>D34,(E34-D34),0) -> 246.6113 | G34: =F34/D34 -> 0.44188074 | K34: Industrial | L34: Aerospace/Defense | M34: {=_xlfn.XLOOKUP(L34,$B$2:B104,$G$2:G104)} -> 0.53675691 | N34: =TRIMMEAN(M34:M47,0.05) -> 0.36891817 | O34: =L14 -> 0.1733
B35: Farming/Agriculture | C35: 48 | D35: 1343.0171 | E35: 2489.184 | F35: =IF(E35>D35,(E35-D35),0) -> 1146.1669 | G35: =F35/D35 -> 0.85342693 | L35: Building Materials | M35: {=_xlfn.XLOOKUP(L35,$B$2:B105,$G$2:G105)} -> 0.80483332
B36: Financial Svcs. (Non-bank & Insurance) | C36: 147 | D36: 8386.0802 | E36: 12301.124 | F36: =IF(E36>D36,(E36-D36),0) -> 3915.0438 | G36: =F36/D36 -> 0.46685027 | L36: Construction Supplies | M36: {=_xlfn.XLOOKUP(L36,$B$2:B106,$G$2:G106)} -> 0.41541742
B37: Food Processing | C37: 178 | D37: 15818.515 | E37: 23951.348 | F37: =IF(E37>D37,(E37-D37),0) -> 8132.8335 | G37: =F37/D37 -> 0.51413383 | L37: Electrical Equipment | M37: {=_xlfn.XLOOKUP(L37,$B$2:B107,$G$2:G107)} -> 0.56885445
B38: Food Wholesalers | C38: 12 | D38: 300.415 | E38: 316.25 | F38: =IF(E38>D38,(E38-D38),0) -> 15.835 | G38: =F38/D38 -> 0.052710417 | L38: Engineering/Construction | M38: {=_xlfn.XLOOKUP(L38,$B$2:B108,$G$2:G108)} -> 0.43086013
B39: Furn/Home Furnishings | C39: 52 | D39: 407.42756 | E39: 514.485 | F39: =IF(E39>D39,(E39-D39),0) -> 107.05744 | G39: =F39/D39 -> 0.26276435 | L39: Machinery | M39: {=_xlfn.XLOOKUP(L39,$B$2:B109,$G$2:G109)} -> 0.14227208
B40: Green & Renewable Energy | C40: 63 | D40: 862.4886 | E40: 1888.051 | F40: =IF(E40>D40,(E40-D40),0) -> 1025.5624 | G40: =F40/D40 -> 1.1890736 | L40: Packaging & Container | M40: {=_xlfn.XLOOKUP(L40,$B$2:B110,$G$2:G110)} -> 0.048380376
...
